Workbook

Sheet README
A1: Platzi FP&A Financial Model
A2: WP40 deliverable D1. Built by work/WP40_model/build_model.py -- rerun that script to regenerate this file from db/platzi.duckdb + the WP21/WP31 sheet_inputs.csv exports.
A4: Purpose
B5: This workbook holds the assumptions, unit economics and scenario model for Platzi's FP&A take-home
B6: challenge, with every number traceable to a formula, an assumption ID, or a named SQL mart export.
B7: The heavy data work (fact tables, MRR bridge, retention, NDR decomposition, CAC/LTV synthesis, the
B8: scenario simulation engine) lives in the SQL/DuckDB pipeline (sql/staging -> sql/intermediate ->
B9: sql/marts, plus sql/python_models/scenarios.py). This Sheet consumes that pipeline's outputs as
B10: 'Data_*' tabs (verbatim exports of named marts) and rebuilds the assumptions, unit-economics and
B11: scenario CALCULATIONS on top of them with visible spreadsheet formulas, per the 2026-09-26 update
B12: to Docs/Deliverables_Framework.md (D1): 'the data and calculation layer is SQL ... a small Google
B13: Sheet holds Assumptions, Unit Economics and Scenarios with visible formulas, fed by mart exports.'
A15: Tab map
A16: Tab | B16: Contents
A17: README | B17: This tab.
A18: Assumptions | B18: Every driver with an ID (A-xx/D-xx/A2-xx/S-xx), value, unit, source, note. Scenario selector, GM-basis selector, lifetime-cap, benchmarks, starting stock, scenario engine drivers, and the full WP21/WP31 assumption registers.
A19: Data_MRR | B19: Monthly MRR bridge by segment (mart_mrr_bridge): opening/new/expansion/contraction/churn/closing MRR + active customers, Jan-23..Apr-24.
A20: Data_Costs | B20: Monthly marketing spend by segment x channel (stg_marketing_spend), support costs by category (stg_support_costs), and new paying customers by month x segment (mart_a2_01_new_paying_customers).
A21: Data_Survival | B21: Logo and $ survival curves by segment, k=0..15 months (mart_a2_10_survival_curve).
A22: Answers_Q1_Q4 | B22: The 4 ad-hoc answers. Q1 (MRR) and Q3 (active subs) are rebuilt with formulas from Data_MRR / a small Q3 data block. Q2 (Q1-24 retention) and Q4 (NDR T12M) link to small data blocks exported from mart_q2_retention_q1_24 / mart_q4_ndr_t12m -- a full formula rebuild would require the row-level subscription table, which is out of this workbook's scope (that computation lives in SQL); this is stated on the tab.
A23: UnitEconomics | B23: Fully loaded CAC, revenue, COGS, GM% (driven by the GM-basis selector), ARPA, the 60-month survival-curve build, LTV, LTV:CAC, CAC payback, and the retention-adjusted payback on the full 60-month curve, by segment. Includes a GM-basis x lifetime-cap sensitivity grid.
A24: Scenarios | B24: A 12-month (May-24..Apr-25) formula-driven projection by segment, in three parallel Base/Bull/Bear blocks (no selector needed), plus a summary and a reconciliation block against the Python scenario engine (mart_s_03_scenario_summary).
A25: Strategies | B25: The WP23 retention-strategy table (6mo/12mo MRR delta, NDR delta, effort), linked to Assumptions where the impact is a simple formula, labelled 'from engine' where it comes from the Python simulation.
A26: Checks | B26: TRUE/FALSE reconciliation checks with a master ALL CHECKS PASS cell.
A28: Conventions
A29: Convention | B29: Meaning
A30: Blue font | B30: Hard-coded input (an assumption, or a value pasted from a SQL mart export on a Data_* tab).
A31: Black font | B31: A formula computed from other cells in this workbook.
A32: Green font | B32: A formula that links to a value on another tab (a cross-sheet reference / lookup).
A33: No hard-coded numbers in formulas | B33: Every formula points at an Assumptions/Data_* cell instead of embedding a number, except structural constants (12 months/year, 1).
A34: No macros / data tables / structured refs / dynamic-array-only functions / external links | B34: Only SUM, SUMIFS, SUMPRODUCT, INDEX/MATCH, IF, MIN/MAX, ROUND, AVERAGE, COUNTIFS, IFERROR, AND/OR and basic arithmetic are used, so the workbook opens and recalculates identically in Excel and Google Sheets.
A36: Data window
B37: Historical data: Jan-2023 .. Apr-2024 (16 months). As-of / snapshot date (M-01): 2024-04-30.
B38: Scenario projection: May-2024 .. Apr-2025 (12 months), seeded from the Apr-24 actuals.
B39: CAC / GM / ARPA windows: T6M = Nov-2023..Apr-2024 (base); T16M = Jan-2023..Apr-2024 (reference).
A41: How this links to the SQL pipeline
B42: Every Data_* tab is a verbatim export of one or more named marts/staging tables from db/platzi.duckdb
B43: (built by sql/run_pipeline.py from sql/staging -> sql/intermediate -> sql/marts, plus the Python
B44: scenario engine in sql/python_models/scenarios.py). This workbook does NOT recompute the SQL layer's
B45: own logic (retention definitions, the survival-curve tail-rate cascade, the monthly compartment
...

Sheet Assumptions
A1: Assumptions
A2: Purpose: every input driver used anywhere in this workbook, with its ID, value, unit, source and note. Source = sql/marts/*.sql, sql/python_models/scenarios.py, or a WP results.md. Blue = hard-coded input pasted from the SQL layer or the brief; nothing on this tab is a formula.
A4: Key selectors & horizon dates
A5: Label | B5: Value | C5: Unit | D5: Source | E5: Note
A6: Scenario selector (informational -- Scenarios tab computes Base/Bull/Bear in parallel blocks, so no tab actually reads this cell) | B6: Base | C6: Base/Bull/Bear | D6: brief | E6: dropdown; kept for spec compliance / manual what-if reading
A7: GM basis selector | B7: T6M avg | C7: T6M avg/Apr-24 run-rate | D7: D-17 | E7: T6M avg 29.3%% (conservative, base) vs Apr-24 run-rate 40.9%% (upside sensitivity); drives GM% and LTV on UnitEconomics
A8: LTV horizon cap -- base | B8: 60 | C8: months | D8: A-18 | E8: proposed WP21; standard 5-yr SaaS planning horizon
A9: LTV horizon cap -- sensitivity | B9: 36 | C9: months | D9: A-18 | E9: conservative alternative reported alongside the 60mo base
A10: As-of / snapshot date (M-01) | B10: 45412 | C10: date | D10: M-01 | E10: April 2024 = snapshot at 2024-04-30
A11: T6M window start (month-end basis, for Data_MRR) | B11: 45260 | C11: date | D11: D-19/WP21 | E11: Nov-23..Apr-24
A12: T6M window start (month-start basis, for Data_Costs) | B12: 45231 | C12: date | D12: D-19/WP21 | E12: stg_marketing_spend/stg_support_costs use month-start dates
A13: T6M window end (month-start basis, for Data_Costs) | B13: 45383 | C13: date | D13: D-19/WP21
A14: T16M window start (month-end basis, for Data_MRR) | B14: 44957 | C14: date | D14: WP21 | E14: Jan-23..Apr-24
A15: T16M window start (month-start basis, for Data_Costs) | B15: 44927 | C15: date | D15: WP21
A16: Scenario horizon start (month 1 = May-24) | B16: 45443 | C16: date | D16: brief/WP31 | E16: 12-month projection starts the month after the as-of date
A17: Scenario horizon end (month 12 = Apr-25) | B17: 45777 | C17: date | D17: brief/WP31
A18: Benchmark: LTV:CAC | B18: 3 | C18: x | D18: brief/A2-012 | E18: SaaS rule of thumb, all segments
A19: Benchmark: CAC payback, B2C/SMB | B19: 12 | C19: months | D19: brief/A2-012
A20: Benchmark: CAC payback, Enterprise | B20: 18 | C20: months | D20: brief/A2-012 | E20: longer sales cycle allowance
A21: Tolerance: scenario reconciliation vs engine | B21: 0.03 | C21: relative % | D21: WP40 spec | E21: target <= 3% on Apr-25 total MRR per scenario
A22: Tolerance: scenario reconciliation, single segment | B22: 0.05 | C22: relative % | D22: Lead review (D-20) | E22: segment-level gaps are larger on small bases (e.g. SMB Bull stacks 3 levers); totals keep 3%
A23: Tolerance: sheet CAC/LTV vs mart_a2_12 | B23: 0.01 | C23: relative % | D23: WP40 spec
A24: QA target: Q1 total MRR Apr-24 | B24: 204709.09 | C24: USD | D24: mart_q1_mrr_apr24 | E24: sum of segments must tie to this
A25: QA target: Q3 total active subs Apr-24 | B25: 1941 | C25: customers | D25: mart_q3_active_subs_apr24
A27: Starting stock -- Apr-24 actuals (source: mart_q3_active_subs_apr24)
A28: Segment | B28: Plan type | C28: Active subs (Apr-24)
A29: B2C | B29: annual | C29: 692
A30: B2C | B30: monthly | C30: 844
A31: Enterprise | B31: annual | C31: 90
A32: Enterprise | B32: monthly | C32: 12
A33: SMB | B33: annual | C33: 190
A34: SMB | B34: monthly | C34: 113
A36: Starting MRR & customers -- Apr-24 actuals (link to Data_MRR)
A37: Segment | B37: Opening MRR (Apr-24) | C37: Opening customers (Apr-24)
A38: B2C | B38: =SUMIFS(Data_MRR!$H:$H,Data_MRR!$B:$B,"B2C",Data_MRR!$A:$A,Assumptions!$B$10) | C38: =SUMIFS(Data_MRR!$I:$I,Data_MRR!$B:$B,"B2C",Data_MRR!$A:$A,Assumptions!$B$10)
A39: SMB | B39: =SUMIFS(Data_MRR!$H:$H,Data_MRR!$B:$B,"SMB",Data_MRR!$A:$A,Assumptions!$B$10) | C39: =SUMIFS(Data_MRR!$I:$I,Data_MRR!$B:$B,"SMB",Data_MRR!$A:$A,Assumptions!$B$10)
A40: Enterprise | B40: =SUMIFS(Data_MRR!$H:$H,Data_MRR!$B:$B,"Enterprise",Data_MRR!$A:$A,Assumptions!$B$10) | C40: =SUMIFS(Data_MRR!$I:$I,Data_MRR!$B:$B,"Enterprise",Data_MRR!$A:$A,Assumptions!$B$10)
A42: Survival-curve tail parameters (Proposed A-23; source: mart_a2_11_lifetime.sql)
A43: Segment | B43: Reliable horizon k_rel (months) | C43: Dollar tail decay/mo | D43: Logo tail churn/mo
A44: B2C | B44: 15 | C44: 0.049429713 | D44: 0.035159717
...

Sheet Data_MRR
A1: Data_MRR
A2: Source: mart_mrr_bridge.sql (verbatim export). Monthly MRR bridge by segment, Jan-23..Apr-24: opening -> +new +expansion -contraction -churn -> closing, plus active customers. Blank expansion/contraction/churn cells = $0 (no movement of that type that month) -- treated as 0 in all downstream formulas.
A4: month_end | B4: segment | C4: opening_mrr | D4: new_mrr | E4: expansion_mrr | F4: contraction_mrr | G4: churn_mrr | H4: closing_mrr | I4: active_customers | J4: bridge_check (opening+new+exp-contr-churn=closing)
A5: 44957 | B5: B2B | C5: 0 | D5: 3195.6 | H5: 3195.6 | I5: 11 | J5: =ROUND(IFERROR(C5,0)+IFERROR(D5,0)+IFERROR(E5,0)-IFERROR(F5,0)-IFERROR(G5,0)-IFERROR(H5,0),2)=0
A6: 44985 | B6: B2B | C6: 3195.6 | D6: 4260.12 | E6: 54.51 | F6: 39.28 | H6: 7470.95 | I6: 28 | J6: =ROUND(IFERROR(C6,0)+IFERROR(D6,0)+IFERROR(E6,0)-IFERROR(F6,0)-IFERROR(G6,0)-IFERROR(H6,0),2)=0
A7: 45016 | B7: B2B | C7: 7470.95 | D7: 7130.44 | H7: 14601.39 | I7: 49 | J7: =ROUND(IFERROR(C7,0)+IFERROR(D7,0)+IFERROR(E7,0)-IFERROR(F7,0)-IFERROR(G7,0)-IFERROR(H7,0),2)=0
A8: 45046 | B8: B2B | C8: 14601.39 | D8: 5855.68 | E8: 66.39 | F8: 32.92 | G8: 1189 | H8: 19301.54 | I8: 64 | J8: =ROUND(IFERROR(C8,0)+IFERROR(D8,0)+IFERROR(E8,0)-IFERROR(F8,0)-IFERROR(G8,0)-IFERROR(H8,0),2)=0
A9: 45077 | B9: B2B | C9: 19301.54 | D9: 9365.04 | E9: 158.72 | G9: 231.72 | H9: 28593.58 | I9: 91 | J9: =ROUND(IFERROR(C9,0)+IFERROR(D9,0)+IFERROR(E9,0)-IFERROR(F9,0)-IFERROR(G9,0)-IFERROR(H9,0),2)=0
A10: 45107 | B10: B2B | C10: 28593.58 | D10: 7561.28 | E10: 127.71 | F10: 47.5 | G10: 2378 | H10: 33857.07 | I10: 109 | J10: =ROUND(IFERROR(C10,0)+IFERROR(D10,0)+IFERROR(E10,0)-IFERROR(F10,0)-IFERROR(G10,0)-IFERROR(H10,0),2)=0
A11: 45138 | B11: B2B | C11: 33857.07 | D11: 9561.36 | E11: 106.15 | F11: 220.44 | G11: 396.93 | H11: 42907.21 | I11: 135 | J11: =ROUND(IFERROR(C11,0)+IFERROR(D11,0)+IFERROR(E11,0)-IFERROR(F11,0)-IFERROR(G11,0)-IFERROR(H11,0),2)=0
A12: 45169 | B12: B2B | C12: 42907.21 | D12: 7978.2 | E12: 394.11 | F12: 83.58 | G12: 995 | H12: 50200.94 | I12: 156 | J12: =ROUND(IFERROR(C12,0)+IFERROR(D12,0)+IFERROR(E12,0)-IFERROR(F12,0)-IFERROR(G12,0)-IFERROR(H12,0),2)=0
A13: 45199 | B13: B2B | C13: 50200.94 | D13: 9780.8 | E13: 694.3 | F13: 64.87 | G13: 325.85 | H13: 60285.32 | I13: 184 | J13: =ROUND(IFERROR(C13,0)+IFERROR(D13,0)+IFERROR(E13,0)-IFERROR(F13,0)-IFERROR(G13,0)-IFERROR(H13,0),2)=0
A14: 45230 | B14: B2B | C14: 60285.32 | D14: 9679.96 | E14: 247.75 | F14: 75.2 | G14: 1297.78 | H14: 68840.05 | I14: 207 | J14: =ROUND(IFERROR(C14,0)+IFERROR(D14,0)+IFERROR(E14,0)-IFERROR(F14,0)-IFERROR(G14,0)-IFERROR(H14,0),2)=0
A15: 45260 | B15: B2B | C15: 68840.05 | D15: 11991.12 | E15: 323.42 | F15: 32.51 | G15: 619.75 | H15: 80502.33 | I15: 237 | J15: =ROUND(IFERROR(C15,0)+IFERROR(D15,0)+IFERROR(E15,0)-IFERROR(F15,0)-IFERROR(G15,0)-IFERROR(H15,0),2)=0
A16: 45291 | B16: B2B | C16: 80502.33 | D16: 12984.96 | E16: 490.81 | F16: 39.06 | G16: 3422.57 | H16: 90516.47 | I16: 261 | J16: =ROUND(IFERROR(C16,0)+IFERROR(D16,0)+IFERROR(E16,0)-IFERROR(F16,0)-IFERROR(G16,0)-IFERROR(H16,0),2)=0
A17: 45322 | B17: B2B | C17: 90516.47 | D17: 13236.88 | E17: 562.92 | F17: 241.39 | G17: 1459.44 | H17: 102615.44 | I17: 294 | J17: =ROUND(IFERROR(C17,0)+IFERROR(D17,0)+IFERROR(E17,0)-IFERROR(F17,0)-IFERROR(G17,0)-IFERROR(H17,0),2)=0
A18: 45351 | B18: B2B | C18: 102615.44 | D18: 14049.48 | E18: 678.69 | F18: 296.23 | G18: 2142.42 | H18: 114904.96 | I18: 331 | J18: =ROUND(IFERROR(C18,0)+IFERROR(D18,0)+IFERROR(E18,0)-IFERROR(F18,0)-IFERROR(G18,0)-IFERROR(H18,0),2)=0
A19: 45382 | B19: B2B | C19: 114904.96 | D19: 14627.56 | E19: 390.39 | F19: 50.82 | G19: 1936.28 | H19: 127935.81 | I19: 368 | J19: =ROUND(IFERROR(C19,0)+IFERROR(D19,0)+IFERROR(E19,0)-IFERROR(F19,0)-IFERROR(G19,0)-IFERROR(H19,0),2)=0
A20: 45412 | B20: B2B | C20: 127935.81 | D20: 13902.24 | E20: 697.93 | F20: 112 | G20: 2079.89 | H20: 140344.09 | I20: 405 | J20: =ROUND(IFERROR(C20,0)+IFERROR(D20,0)+IFERROR(E20,0)-IFERROR(F20,0)-IFERROR(G20,0)-IFERROR(H20,0),2)=0
A21: 44957 | B21: B2C | C21: 0 | D21: 3969 | H21: 3969 | I21: 90 | J21: =ROUND(IFERROR(C21,0)+IFERROR(D21,0)+IFERROR(E21,0)-IFERROR(F21,0)-IFERROR(G21,0)-IFERROR(H21,0),2)=0
A22: 44985 | B22: B2C | C22: 3969 | D22: 3739.75 | G22: 392 | H22: 7316.75 | I22: 167 | J22: =ROUND(IFERROR(C22,0)+IFERROR(D22,0)+IFERROR(E22,0)-IFERROR(F22,0)-IFERROR(G22,0)-IFERROR(H22,0),2)=0
A23: 45016 | B23: B2C | C23: 7316.75 | D23: 4588.5 | G23: 343 | H23: 11562.25 | I23: 262 | J23: =ROUND(IFERROR(C23,0)+IFERROR(D23,0)+IFERROR(E23,0)-IFERROR(F23,0)-IFERROR(G23,0)-IFERROR(H23,0),2)=0
A24: 45046 | B24: B2C | C24: 11562.25 | D24: 4740.75 | G24: 833 | H24: 15470 | I24: 353 | J24: =ROUND(IFERROR(C24,0)+IFERROR(D24,0)+IFERROR(E24,0)-IFERROR(F24,0)-IFERROR(G24,0)-IFERROR(H24,0),2)=0
A25: 45077 | B25: B2C | C25: 15470 | D25: 4611.25 | G25: 1176 | H25: 18905.25 | I25: 435 | J25: =ROUND(IFERROR(C25,0)+IFERROR(D25,0)+IFERROR(E25,0)-IFERROR(F25,0)-IFERROR(G25,0)-IFERROR(H25,0),2)=0
A26: 45107 | B26: B2C | C26: 18905.25 | D26: 5544 | G26: 1617 | H26: 22832.25 | I26: 528 | J26: =ROUND(IFERROR(C26,0)+IFERROR(D26,0)+IFERROR(E26,0)-IFERROR(F26,0)-IFERROR(G26,0)-IFERROR(H26,0),2)=0
A27: 45138 | B27: B2C | C27: 22832.25 | D27: 5372.5 | G27: 1078 | H27: 27126.75 | I27: 624 | J27: =ROUND(IFERROR(C27,0)+IFERROR(D27,0)+IFERROR(E27,0)-IFERROR(F27,0)-IFERROR(G27,0)-IFERROR(H27,0),2)=0
A28: 45169 | B28: B2C | C28: 27126.75 | D28: 5836.25 | G28: 1911 | H28: 31052 | I28: 716 | J28: =ROUND(IFERROR(C28,0)+IFERROR(D28,0)+IFERROR(E28,0)-IFERROR(F28,0)-IFERROR(G28,0)-IFERROR(H28,0),2)=0
A29: 45199 | B29: B2C | C29: 31052 | D29: 6443.5 | G29: 2450 | H29: 35045.5 | I29: 811 | J29: =ROUND(IFERROR(C29,0)+IFERROR(D29,0)+IFERROR(E29,0)-IFERROR(F29,0)-IFERROR(G29,0)-IFERROR(H29,0),2)=0
A30: 45230 | B30: B2C | C30: 35045.5 | D30: 7071.75 | G30: 2744 | H30: 39373.25 | I30: 917 | J30: =ROUND(IFERROR(C30,0)+IFERROR(D30,0)+IFERROR(E30,0)-IFERROR(F30,0)-IFERROR(G30,0)-IFERROR(H30,0),2)=0
A31: 45260 | B31: B2C | C31: 39373.25 | D31: 6676.25 | G31: 2842 | H31: 43207.5 | I31: 1011 | J31: =ROUND(IFERROR(C31,0)+IFERROR(D31,0)+IFERROR(E31,0)-IFERROR(F31,0)-IFERROR(G31,0)-IFERROR(H31,0),2)=0
A32: 45291 | B32: B2C | C32: 43207.5 | D32: 7103.25 | G32: 3381 | H32: 46929.75 | I32: 1104 | J32: =ROUND(IFERROR(C32,0)+IFERROR(D32,0)+IFERROR(E32,0)-IFERROR(F32,0)-IFERROR(G32,0)-IFERROR(H32,0),2)=0
A33: 45322 | B33: B2C | C33: 46929.75 | D33: 7269.5 | G33: 3724 | H33: 50475.25 | I33: 1195 | J33: =ROUND(IFERROR(C33,0)+IFERROR(D33,0)+IFERROR(E33,0)-IFERROR(F33,0)-IFERROR(G33,0)-IFERROR(H33,0),2)=0
... A36: 45412 | B36: B2C | C36: 59468.5 | D36: 8800.75 | G36: 3904.25 | H36: 64365 | I36: 1536 | J36: =ROUND(IFERROR(C36,0)+IFERROR(D36,0)+IFERROR(E36,0)-IFERROR(F36,0)-IFERROR(G36,0)-IFERROR(H36,0),2)=0
A37: 44957 | B37: Enterprise | C37: 0 | D37: 1650 | H37: 1650 | I37: 2 | J37: =ROUND(IFERROR(C37,0)+IFERROR(D37,0)+IFERROR(E37,0)-IFERROR(F37,0)-IFERROR(G37,0)-IFERROR(H37,0),2)=0
A38: 44985 | B38: Enterprise | C38: 1650 | D38: 1815 | H38: 3465 | I38: 4 | J38: =ROUND(IFERROR(C38,0)+IFERROR(D38,0)+IFERROR(E38,0)-IFERROR(F38,0)-IFERROR(G38,0)-IFERROR(H38,0),2)=0
A39: 45016 | B39: Enterprise | C39: 3465 | D39: 4290 | H39: 7755 | I39: 9 | J39: =ROUND(IFERROR(C39,0)+IFERROR(D39,0)+IFERROR(E39,0)-IFERROR(F39,0)-IFERROR(G39,0)-IFERROR(H39,0),2)=0
A40: 45046 | B40: Enterprise | C40: 7755 | D40: 3465 | G40: 990 | H40: 10230 | I40: 12 | J40: =ROUND(IFERROR(C40,0)+IFERROR(D40,0)+IFERROR(E40,0)-IFERROR(F40,0)-IFERROR(G40,0)-IFERROR(H40,0),2)=0
A41: 45077 | B41: Enterprise | C41: 10230 | D41: 5775 | H41: 16005 | I41: 19 | J41: =ROUND(IFERROR(C41,0)+IFERROR(D41,0)+IFERROR(E41,0)-IFERROR(F41,0)-IFERROR(G41,0)-IFERROR(H41,0),2)=0
A42: 45107 | B42: Enterprise | C42: 16005 | D42: 4620 | G42: 1980 | H42: 18645 | I42: 22 | J42: =ROUND(IFERROR(C42,0)+IFERROR(D42,0)+IFERROR(E42,0)-IFERROR(F42,0)-IFERROR(G42,0)-IFERROR(H42,0),2)=0
A43: 45138 | B43: Enterprise | C43: 18645 | D43: 5775 | E43: 59.82 | F43: 194.74 | H43: 24285.08 | I43: 29 | J43: =ROUND(IFERROR(C43,0)+IFERROR(D43,0)+IFERROR(E43,0)-IFERROR(F43,0)-IFERROR(G43,0)-IFERROR(H43,0),2)=0
...

Sheet Data_Costs
A1: Data_Costs
A2: Source: stg_marketing_spend, stg_support_costs, mart_a2_01_new_paying_customers (verbatim exports). Three blocks: marketing spend by segment x channel, support costs by category (incl. G&A), and new paying customers by month x segment.
A4: Block A -- Marketing spend by segment x channel (stg_marketing_spend)
A5: month | B5: segment | C5: channel | D5: spend | E5: new_users_acquired
A6: 44927 | B6: B2C | C6: Content | D6: 4804.82 | E6: 150
A7: 44927 | B7: B2C | C7: Organic | D7: 3100.99 | E7: 210
A8: 44927 | B8: B2C | C8: Paid Search | D8: 15854.35 | E8: 290
A9: 44927 | B9: B2C | C9: Paid Social | D9: 11150.23 | E9: 233
A10: 44927 | B10: Enterprise | C10: Content | D10: 3268.88 | E10: 0
A11: 44927 | B11: Enterprise | C11: Sales Team | D11: 17514.6 | E11: 3
A12: 44927 | B12: SMB | C12: Content | D12: 2220.16 | E12: 8
A13: 44927 | B13: SMB | C13: Paid Search | D13: 4325.02 | E13: 15
A14: 44927 | B14: SMB | C14: Paid Social | D14: 3437.9 | E14: 9
A15: 44958 | B15: B2C | C15: Content | D15: 5557.39 | E15: 189
A16: 44958 | B16: B2C | C16: Organic | D16: 3258.38 | E16: 249
A17: 44958 | B17: B2C | C17: Paid Search | D17: 14003.44 | E17: 295
... A149: 45383 | B149: SMB | C149: Paid Social | D149: 7055.92 | E149: 14
A151: Block B -- Support costs by category, incl. G&A (stg_support_costs)
A152: month | B152: category | C152: amount
A153: 44927 | B153: CS Salaries | C153: 30417.51
A154: 44927 | B154: Content Production | C154: 23288.62
A155: 44927 | B155: G&A | C155: 22014.85
A156: 44927 | B156: Infrastructure | C156: 19317.85
A157: 44958 | B157: CS Salaries | C157: 33890.33
A158: 44958 | B158: Content Production | C158: 26492.33
A159: 44958 | B159: G&A | C159: 21940.26
A160: 44958 | B160: Infrastructure | C160: 17941.03
A161: 44986 | B161: CS Salaries | C161: 34952.8
A162: 44986 | B162: Content Production | C162: 28516.62
A163: 44986 | B163: G&A | C163: 24450.65
A164: 44986 | B164: Infrastructure | C164: 20105.1
... A216: 45383 | B216: Infrastructure | C216: 30597.71
A218: Block C -- New paying customers by month x segment (mart_a2_01_new_paying_customers)
A219: month | B219: segment | C219: new_paying_customers
A220: 44927 | B220: B2B | C220: 11
A221: 44927 | B221: B2C | C221: 90
A222: 44927 | B222: Enterprise | C222: 2
A223: 44927 | B223: SMB | C223: 9
A224: 44927 | B224: Total | C224: 101
A225: 44958 | B225: B2B | C225: 17
...

Sheet Data_Survival
A1: Data_Survival
A2: Source: mart_a2_10_survival_curve.sql (verbatim export). Logo and dollar survival curves by segment, k=0..15 months since signup. Used by UnitEconomics to build the 60-month lifetime curve (observed k=0..k_rel, then an extrapolated tail).
A4: segment | B4: k | C4: exposed_n | D4: active_n | E4: logo_survival | F4: mrr_at_k_sum | G4: mrr_at_0_sum | H4: dollar_retention | I4: arpa_at_signup
A5: B2B | B5: 0 | C5: 470 | D5: 469 | E5: 0.9979 | F5: 155160.72 | G5: 155160.72 | H5: 1 | I5: 330.13
A6: B2B | B6: 1 | C6: 427 | D6: 416 | E6: 0.9742 | F6: 139866.53 | G6: 141258.48 | H6: 0.9901 | I6: 330.82
A7: B2B | B7: 2 | C7: 383 | D7: 359 | E7: 0.9373 | F7: 121567.6 | G7: 126630.92 | H7: 0.96 | I7: 330.63
A8: B2B | B8: 3 | C8: 340 | D8: 305 | E8: 0.8971 | F8: 104251.39 | G8: 112581.44 | H8: 0.926 | I8: 331.12
A9: B2B | B9: 4 | C9: 300 | D9: 259 | E9: 0.8633 | F9: 90044.1 | G9: 99344.56 | H9: 0.9064 | I9: 331.15
A10: B2B | B10: 5 | C10: 262 | D10: 220 | E10: 0.8397 | F10: 76410.02 | G10: 86359.6 | H10: 0.8848 | I10: 329.62
A11: B2B | B11: 6 | C11: 229 | D11: 189 | E11: 0.8253 | F11: 64619.21 | G11: 74368.48 | H11: 0.8689 | I11: 324.75
A12: B2B | B12: 7 | C12: 200 | D12: 166 | E12: 0.83 | F12: 56628.31 | G12: 64688.52 | H12: 0.8754 | I12: 323.44
A13: B2B | B13: 8 | C13: 170 | D13: 137 | E13: 0.8059 | F13: 46918.15 | G13: 54907.72 | H13: 0.8545 | I13: 322.99
A14: B2B | B14: 9 | C14: 144 | D14: 118 | E14: 0.8194 | F14: 40099.7 | G14: 46929.52 | H14: 0.8545 | I14: 325.9
A15: B2B | B15: 10 | C15: 116 | D15: 95 | E15: 0.819 | F15: 30395.19 | G15: 37368.16 | H15: 0.8134 | I15: 322.14
A16: B2B | B16: 11 | C16: 94 | D16: 77 | E16: 0.8191 | F16: 25161.4 | G16: 29806.88 | H16: 0.8441 | I16: 317.09
... A84: Total | B84: 15 | C84: 101 | D84: 47 | E84: 0.4653 | F84: 4452.65 | G84: 7164.6 | H84: 0.6215 | I84: 70.94

Sheet Answers_Q1_Q4
A1: Answers_Q1_Q4
A2: The four ad-hoc questions. Q1 (MRR by segment) and Q3 (active subs by segment x plan) are rebuilt with formulas from Data_MRR / the Assumptions starting-stock block. Q2 (Q1-24 retention) and Q4 (NDR T12M) link to small data blocks exported from mart_q2_retention_q1_24 / mart_q4_ndr_t12m: their definitions (M-06 renewal-event retention; M-08/M-09/M-10 NDR/GRR/expansion-contraction) require row-level subscription-period data and a customer-level cohort join that are impractical to rebuild as spreadsheet formulas -- that computation lives in SQL (sql/marts/mart_q2_retention_q1_24.sql, mart_q4_ndr_t12m.sql); this tab links the finished mart output instead of re-deriving it.
A4: Q1 -- MRR by segment, Apr-24 (M-01..M-04; formula from Data_MRR)
A5: Segment | B5: MRR Apr-24 | C5: % of total
A6: B2C | B6: =SUMIFS(Data_MRR!$H:$H,Data_MRR!$B:$B,"B2C",Data_MRR!$A:$A,Assumptions!$B$10) | C6: =B6/$B$9
A7: SMB | B7: =SUMIFS(Data_MRR!$H:$H,Data_MRR!$B:$B,"SMB",Data_MRR!$A:$A,Assumptions!$B$10) | C7: =B7/$B$9
A8: Enterprise | B8: =SUMIFS(Data_MRR!$H:$H,Data_MRR!$B:$B,"Enterprise",Data_MRR!$A:$A,Assumptions!$B$10) | C8: =B8/$B$9
A9: Total (= sum of segments) | B9: =SUM(B6:B8) | C9: =B9/$B$9
A11: Q2 -- Q1-2024 retention, B2C vs B2B (M-06 primary; linked from mart_q2_retention_q1_24)
A12: Segment | B12: Logo retention (all plans) | C12: $ retention (all plans)
A13: B2C | B13: =SUMPRODUCT(($A$21:$A$40="B2C")*($B$21:$B$40="all")*($C$21:$C$40="M06_primary")*$G$21:$G$40) | C13: =SUMPRODUCT(($A$21:$A$40="B2C")*($B$21:$B$40="all")*($C$21:$C$40="M06_primary")*$J$21:$J$40)
A14: SMB | B14: =SUMPRODUCT(($A$21:$A$40="SMB")*($B$21:$B$40="all")*($C$21:$C$40="M06_primary")*$G$21:$G$40) | C14: =SUMPRODUCT(($A$21:$A$40="SMB")*($B$21:$B$40="all")*($C$21:$C$40="M06_primary")*$J$21:$J$40)
A15: Enterprise | B15: =SUMPRODUCT(($A$21:$A$40="Enterprise")*($B$21:$B$40="all")*($C$21:$C$40="M06_primary")*$G$21:$G$40) | C15: =SUMPRODUCT(($A$21:$A$40="Enterprise")*($B$21:$B$40="all")*($C$21:$C$40="M06_primary")*$J$21:$J$40)
A16: B2B | B16: =SUMPRODUCT(($A$21:$A$40="B2B")*($B$21:$B$40="all")*($C$21:$C$40="M06_primary")*$G$21:$G$40) | C16: =SUMPRODUCT(($A$21:$A$40="B2B")*($B$21:$B$40="all")*($C$21:$C$40="M06_primary")*$J$21:$J$40)
A17: Total | B17: =SUMPRODUCT(($A$21:$A$40="Total")*($B$21:$B$40="all")*($C$21:$C$40="M06_primary")*$G$21:$G$40) | C17: =SUMPRODUCT(($A$21:$A$40="Total")*($B$21:$B$40="all")*($C$21:$C$40="M06_primary")*$J$21:$J$40)
A19: Data block below: mart_q2_retention_q1_24 (M-06 renewal-event basis: renewed / (renewed + churned), over subscriptions with end_date in 2024-01-01..2024-03-31).
A20: segment | B20: split | C20: method | D20: n_renewed | E20: n_churned | F20: n_ended | G20: logo_rate | H20: dollar_numerator | I20: dollar_denominator | J20: dollar_rate
A21: B2B | B21: all | C21: M06_primary | D21: 301 | E21: 20 | F21: 321 | G21: 0.9377 | H21: 89702.34 | I21: 94196.92 | J21: 0.9523
A22: B2B | B22: all | C22: M07_crosscheck | F22: 261 | G22: 0.9349
A23: B2B | B23: annual | C23: M06_primary | D23: 28 | E23: 2 | F23: 30 | G23: 0.9333 | H23: 8256.49 | I23: 9223.16 | J23: 0.8952
A24: B2B | B24: monthly | C24: M06_primary | D24: 273 | E24: 18 | F24: 291 | G24: 0.9381 | H24: 81445.85 | I24: 84973.76 | J24: 0.9585
A25: B2C | B25: all | C25: M06_primary | D25: 1936 | E25: 226 | F25: 2162 | G25: 0.8955 | H25: 93635.5 | I25: 104662.25 | J25: 0.8946
A26: B2C | B26: all | C26: M07_crosscheck | F26: 1104 | G26: 0.8261
A27: B2C | B27: annual | C27: M06_primary | D27: 78 | E27: 3 | F27: 81 | G27: 0.963 | H27: 2593.5 | I27: 2693.25 | J27: 0.963
A28: B2C | B28: monthly | C28: M06_primary | D28: 1858 | E28: 223 | F28: 2081 | G28: 0.8928 | H28: 91042 | I28: 101969 | J28: 0.8928
A29: Enterprise | B29: all | C29: M06_primary | D29: 31 | E29: 2 | F29: 33 | G29: 0.9394 | H29: 30443.54 | I29: 32187.37 | J29: 0.9458
A30: Enterprise | B30: all | C30: M07_crosscheck | F30: 66 | G30: 0.9697
A31: Enterprise | B31: annual | C31: M06_primary | D31: 6 | E31: 1 | F31: 7 | G31: 0.8571 | H31: 4864.99 | I31: 5775 | J31: 0.8424
A32: Enterprise | B32: monthly | C32: M06_primary | D32: 25 | E32: 1 | F32: 26 | G32: 0.9615 | H32: 25578.55 | I32: 26412.37 | J32: 0.9684
A33: SMB | B33: all | C33: M06_primary | D33: 270 | E33: 18 | F33: 288 | G33: 0.9375 | H33: 59258.8 | I33: 62009.55 | J33: 0.9556
A34: SMB | B34: all | C34: M07_crosscheck | F34: 195 | G34: 0.9231
A35: SMB | B35: annual | C35: M06_primary | D35: 22 | E35: 1 | F35: 23 | G35: 0.9565 | H35: 3391.5 | I35: 3448.16 | J35: 0.9836
A36: SMB | B36: monthly | C36: M06_primary | D36: 248 | E36: 17 | F36: 265 | G36: 0.9358 | H36: 55867.3 | I36: 58561.39 | J36: 0.954
A37: Total | B37: all | C37: M06_primary | D37: 2237 | E37: 246 | F37: 2483 | G37: 0.9009 | H37: 183337.84 | I37: 198859.17 | J37: 0.9219
A38: Total | B38: all | C38: M07_crosscheck | F38: 1365 | G38: 0.8469
A39: Total | B39: annual | C39: M06_primary | D39: 106 | E39: 5 | F39: 111 | G39: 0.955 | H39: 10849.99 | I39: 11916.41 | J39: 0.9105
A40: Total | B40: monthly | C40: M06_primary | D40: 2131 | E40: 241 | F40: 2372 | G40: 0.8984 | H40: 172487.85 | I40: 186942.76 | J40: 0.9227
A42: Q3 -- Active subscriptions, Apr-24, by segment x plan (M-02; formula from Assumptions starting stock)
A43: Segment | B43: Monthly | C43: Annual | D43: Total
A44: B2C | B44: =SUMIFS(Assumptions!$C$29:$C$34,Assumptions!$A$29:$A$34,"B2C",Assumptions!$B$29:$B$34,"monthly") | C44: =SUMIFS(Assumptions!$C$29:$C$34,Assumptions!$A$29:$A$34,"B2C",Assumptions!$B$29:$B$34,"annual") | D44: =B44+C44
...

Sheet UnitEconomics
A1: UnitEconomics
A2: Source: Data_Costs, Data_MRR, Data_Survival + Assumptions (D-05/D-06/D-07, M-12..M-15, A-15..A-18, A-23). Fully loaded CAC, gross margin, ARPA, the 60-month survival-based lifetime curve, LTV, LTV:CAC, CAC payback and the retention-adjusted payback, by segment -- all computed with formulas from the Data_* tabs, cross-checked on the Checks tab against mart_a2_12_unit_economics_summary within 1%.
A4: G&A allocation build (D-05): company-level marketing, COGS (non-G&A support costs) and G&A pool, T6M and T16M
A5: Metric | B5: T6M (Nov-23..Apr-24) | C5: T16M (Jan-23..Apr-24)
A6: Total marketing spend (all segments) | B6: =SUMIFS(Data_Costs!$D$6:$D$149,Data_Costs!$A$6:$A$149,">="&Assumptions!$B$12,Data_Costs!$A$6:$A$149,"<="&Assumptions!$B$13) | C6: =SUMIFS(Data_Costs!$D$6:$D$149,Data_Costs!$A$6:$A$149,">="&Assumptions!$B$15,Data_Costs!$A$6:$A$149,"<="&Assumptions!$B$13)
A7: Total support costs, non-G&A (= company COGS) | B7: =SUMIFS(Data_Costs!$C$153:$C$216,Data_Costs!$B$153:$B$216,"CS Salaries",Data_Costs!$A$153:$A$216,">="&Assumptions!$B$12,Data_Costs!$A$153:$A$216,"<="&Assumptions!$B$13)+SUMIFS(Data_Costs!$C$153:$C$216,Data_Costs!$B$153:$B$216,"Infrastructure",Data_Costs!$A$153:$A$216,">="&Assumptions!$B$12,Data_Costs!$A$153:$A$216,"<="&Assumptions!$B$13)+SUMIFS(Data_Costs!$C$153:$C$216,Data_Costs!$B$153:$B$216,"Content Production",Data_Costs!$A$153:$A$216,">="&Assumptions!$B$12,Data_Costs!$A$153:$A$216,"<="&Assumptions!$B$13) | C7: =SUMIFS(Data_Costs!$C$153:$C$216,Data_Costs!$B$153:$B$216,"CS Salaries",Data_Costs!$A$153:$A$216,">="&Assumptions!$B$15,Data_Costs!$A$153:$A$216,"<="&Assumptions!$B$13)+SUMIFS(Data_Costs!$C$153:$C$216,Data_Costs!$B$153:$B$216,"Infrastructure",Data_Costs!$A$153:$A$216,">="&Assumptions!$B$15,Data_Costs!$A$153:$A$216,"<="&Assumptions!$B$13)+SUMIFS(Data_Costs!$C$153:$C$216,Data_Costs!$B$153:$B$216,"Content Production",Data_Costs!$A$153:$A$216,">="&Assumptions!$B$15,Data_Costs!$A$153:$A$216,"<="&Assumptions!$B$13)
A8: Total G&A | B8: =SUMIFS(Data_Costs!$C$153:$C$216,Data_Costs!$B$153:$B$216,"G&A",Data_Costs!$A$153:$A$216,">="&Assumptions!$B$12,Data_Costs!$A$153:$A$216,"<="&Assumptions!$B$13) | C8: =SUMIFS(Data_Costs!$C$153:$C$216,Data_Costs!$B$153:$B$216,"G&A",Data_Costs!$A$153:$A$216,">="&Assumptions!$B$15,Data_Costs!$A$153:$A$216,"<="&Assumptions!$B$13)
A9: Acquisition share of G&A = marketing / (marketing + COGS) | B9: =B6/(B6+B7) | C9: =C6/(C6+C7)
A10: Allocated G&A pool = acquisition share x total G&A | B10: =B9*B8 | C10: =C9*C8
A12: Monthly ARPA (by segment) & company GM% helper (T6M window, Nov-23..Apr-24). M-12: revenue=MRR, COGS=CS Salaries+Infrastructure+Content, all allocated by MRR share -> GM% is uniform across segments by construction (test_a2_gm_base_uniform)
A13: Month-end | B13: Revenue (Total MRR) | C13: COGS (non-G&A) | D13: GM% (month) | E13: B2C ARPA | F13: SMB ARPA | G13: Enterprise ARPA | I13: Month-start (helper, for Data_Costs lookups)
A14: 45260 | B14: =SUMIFS(Data_MRR!$H$5:$H$84,Data_MRR!$B$5:$B$84,"Total",Data_MRR!$A$5:$A$84,$A14) | C14: =SUMIFS(Data_Costs!$C$153:$C$216,Data_Costs!$B$153:$B$216,"CS Salaries",Data_Costs!$A$153:$A$216,$I14)+SUMIFS(Data_Costs!$C$153:$C$216,Data_Costs!$B$153:$B$216,"Infrastructure",Data_Costs!$A$153:$A$216,$I14)+SUMIFS(Data_Costs!$C$153:$C$216,Data_Costs!$B$153:$B$216,"Content Production",Data_Costs!$A$153:$A$216,$I14) | D14: =1-C14/B14 | E14: =SUMIFS(Data_MRR!$H$5:$H$84,Data_MRR!$B$5:$B$84,"B2C",Data_MRR!$A$5:$A$84,$A14)/SUMIFS(Data_MRR!$I$5:$I$84,Data_MRR!$B$5:$B$84,"B2C",Data_MRR!$A$5:$A$84,$A14) | F14: =SUMIFS(Data_MRR!$H$5:$H$84,Data_MRR!$B$5:$B$84,"SMB",Data_MRR!$A$5:$A$84,$A14)/SUMIFS(Data_MRR!$I$5:$I$84,Data_MRR!$B$5:$B$84,"SMB",Data_MRR!$A$5:$A$84,$A14) | G14: =SUMIFS(Data_MRR!$H$5:$H$84,Data_MRR!$B$5:$B$84,"Enterprise",Data_MRR!$A$5:$A$84,$A14)/SUMIFS(Data_MRR!$I$5:$I$84,Data_MRR!$B$5:$B$84,"Enterprise",Data_MRR!$A$5:$A$84,$A14) | I14: 45231
A15: 45291 | B15: =SUMIFS(Data_MRR!$H$5:$H$84,Data_MRR!$B$5:$B$84,"Total",Data_MRR!$A$5:$A$84,$A15) | C15: =SUMIFS(Data_Costs!$C$153:$C$216,Data_Costs!$B$153:$B$216,"CS Salaries",Data_Costs!$A$153:$A$216,$I15)+SUMIFS(Data_Costs!$C$153:$C$216,Data_Costs!$B$153:$B$216,"Infrastructure",Data_Costs!$A$153:$A$216,$I15)+SUMIFS(Data_Costs!$C$153:$C$216,Data_Costs!$B$153:$B$216,"Content Production",Data_Costs!$A$153:$A$216,$I15) | D15: =1-C15/B15 | E15: =SUMIFS(Data_MRR!$H$5:$H$84,Data_MRR!$B$5:$B$84,"B2C",Data_MRR!$A$5:$A$84,$A15)/SUMIFS(Data_MRR!$I$5:$I$84,Data_MRR!$B$5:$B$84,"B2C",Data_MRR!$A$5:$A$84,$A15) | F15: =SUMIFS(Data_MRR!$H$5:$H$84,Data_MRR!$B$5:$B$84,"SMB",Data_MRR!$A$5:$A$84,$A15)/SUMIFS(Data_MRR!$I$5:$I$84,Data_MRR!$B$5:$B$84,"SMB",Data_MRR!$A$5:$A$84,$A15) | G15: =SUMIFS(Data_MRR!$H$5:$H$84,Data_MRR!$B$5:$B$84,"Enterprise",Data_MRR!$A$5:$A$84,$A15)/SUMIFS(Data_MRR!$I$5:$I$84,Data_MRR!$B$5:$B$84,"Enterprise",Data_MRR!$A$5:$A$84,$A15) | I15: 45261
A16: 45322 | B16: =SUMIFS(Data_MRR!$H$5:$H$84,Data_MRR!$B$5:$B$84,"Total",Data_MRR!$A$5:$A$84,$A16) | C16: =SUMIFS(Data_Costs!$C$153:$C$216,Data_Costs!$B$153:$B$216,"CS Salaries",Data_Costs!$A$153:$A$216,$I16)+SUMIFS(Data_Costs!$C$153:$C$216,Data_Costs!$B$153:$B$216,"Infrastructure",Data_Costs!$A$153:$A$216,$I16)+SUMIFS(Data_Costs!$C$153:$C$216,Data_Costs!$B$153:$B$216,"Content Production",Data_Costs!$A$153:$A$216,$I16) | D16: =1-C16/B16 | E16: =SUMIFS(Data_MRR!$H$5:$H$84,Data_MRR!$B$5:$B$84,"B2C",Data_MRR!$A$5:$A$84,$A16)/SUMIFS(Data_MRR!$I$5:$I$84,Data_MRR!$B$5:$B$84,"B2C",Data_MRR!$A$5:$A$84,$A16) | F16: =SUMIFS(Data_MRR!$H$5:$H$84,Data_MRR!$B$5:$B$84,"SMB",Data_MRR!$A$5:$A$84,$A16)/SUMIFS(Data_MRR!$I$5:$I$84,Data_MRR!$B$5:$B$84,"SMB",Data_MRR!$A$5:$A$84,$A16) | G16: =SUMIFS(Data_MRR!$H$5:$H$84,Data_MRR!$B$5:$B$84,"Enterprise",Data_MRR!$A$5:$A$84,$A16)/SUMIFS(Data_MRR!$I$5:$I$84,Data_MRR!$B$5:$B$84,"Enterprise",Data_MRR!$A$5:$A$84,$A16) | I16: 45292
A17: 45351 | B17: =SUMIFS(Data_MRR!$H$5:$H$84,Data_MRR!$B$5:$B$84,"Total",Data_MRR!$A$5:$A$84,$A17) | C17: =SUMIFS(Data_Costs!$C$153:$C$216,Data_Costs!$B$153:$B$216,"CS Salaries",Data_Costs!$A$153:$A$216,$I17)+SUMIFS(Data_Costs!$C$153:$C$216,Data_Costs!$B$153:$B$216,"Infrastructure",Data_Costs!$A$153:$A$216,$I17)+SUMIFS(Data_Costs!$C$153:$C$216,Data_Costs!$B$153:$B$216,"Content Production",Data_Costs!$A$153:$A$216,$I17) | D17: =1-C17/B17 | E17: =SUMIFS(Data_MRR!$H$5:$H$84,Data_MRR!$B$5:$B$84,"B2C",Data_MRR!$A$5:$A$84,$A17)/SUMIFS(Data_MRR!$I$5:$I$84,Data_MRR!$B$5:$B$84,"B2C",Data_MRR!$A$5:$A$84,$A17) | F17: =SUMIFS(Data_MRR!$H$5:$H$84,Data_MRR!$B$5:$B$84,"SMB",Data_MRR!$A$5:$A$84,$A17)/SUMIFS(Data_MRR!$I$5:$I$84,Data_MRR!$B$5:$B$84,"SMB",Data_MRR!$A$5:$A$84,$A17) | G17: =SUMIFS(Data_MRR!$H$5:$H$84,Data_MRR!$B$5:$B$84,"Enterprise",Data_MRR!$A$5:$A$84,$A17)/SUMIFS(Data_MRR!$I$5:$I$84,Data_MRR!$B$5:$B$84,"Enterprise",Data_MRR!$A$5:$A$84,$A17) | I17: 45323
A18: 45382 | B18: =SUMIFS(Data_MRR!$H$5:$H$84,Data_MRR!$B$5:$B$84,"Total",Data_MRR!$A$5:$A$84,$A18) | C18: =SUMIFS(Data_Costs!$C$153:$C$216,Data_Costs!$B$153:$B$216,"CS Salaries",Data_Costs!$A$153:$A$216,$I18)+SUMIFS(Data_Costs!$C$153:$C$216,Data_Costs!$B$153:$B$216,"Infrastructure",Data_Costs!$A$153:$A$216,$I18)+SUMIFS(Data_Costs!$C$153:$C$216,Data_Costs!$B$153:$B$216,"Content Production",Data_Costs!$A$153:$A$216,$I18) | D18: =1-C18/B18 | E18: =SUMIFS(Data_MRR!$H$5:$H$84,Data_MRR!$B$5:$B$84,"B2C",Data_MRR!$A$5:$A$84,$A18)/SUMIFS(Data_MRR!$I$5:$I$84,Data_MRR!$B$5:$B$84,"B2C",Data_MRR!$A$5:$A$84,$A18) | F18: =SUMIFS(Data_MRR!$H$5:$H$84,Data_MRR!$B$5:$B$84,"SMB",Data_MRR!$A$5:$A$84,$A18)/SUMIFS(Data_MRR!$I$5:$I$84,Data_MRR!$B$5:$B$84,"SMB",Data_MRR!$A$5:$A$84,$A18) | G18: =SUMIFS(Data_MRR!$H$5:$H$84,Data_MRR!$B$5:$B$84,"Enterprise",Data_MRR!$A$5:$A$84,$A18)/SUMIFS(Data_MRR!$I$5:$I$84,Data_MRR!$B$5:$B$84,"Enterprise",Data_MRR!$A$5:$A$84,$A18) | I18: 45352
A19: 45412 | B19: =SUMIFS(Data_MRR!$H$5:$H$84,Data_MRR!$B$5:$B$84,"Total",Data_MRR!$A$5:$A$84,$A19) | C19: =SUMIFS(Data_Costs!$C$153:$C$216,Data_Costs!$B$153:$B$216,"CS Salaries",Data_Costs!$A$153:$A$216,$I19)+SUMIFS(Data_Costs!$C$153:$C$216,Data_Costs!$B$153:$B$216,"Infrastructure",Data_Costs!$A$153:$A$216,$I19)+SUMIFS(Data_Costs!$C$153:$C$216,Data_Costs!$B$153:$B$216,"Content Production",Data_Costs!$A$153:$A$216,$I19) | D19: =1-C19/B19 | E19: =SUMIFS(Data_MRR!$H$5:$H$84,Data_MRR!$B$5:$B$84,"B2C",Data_MRR!$A$5:$A$84,$A19)/SUMIFS(Data_MRR!$I$5:$I$84,Data_MRR!$B$5:$B$84,"B2C",Data_MRR!$A$5:$A$84,$A19) | F19: =SUMIFS(Data_MRR!$H$5:$H$84,Data_MRR!$B$5:$B$84,"SMB",Data_MRR!$A$5:$A$84,$A19)/SUMIFS(Data_MRR!$I$5:$I$84,Data_MRR!$B$5:$B$84,"SMB",Data_MRR!$A$5:$A$84,$A19) | G19: =SUMIFS(Data_MRR!$H$5:$H$84,Data_MRR!$B$5:$B$84,"Enterprise",Data_MRR!$A$5:$A$84,$A19)/SUMIFS(Data_MRR!$I$5:$I$84,Data_MRR!$B$5:$B$84,"Enterprise",Data_MRR!$A$5:$A$84,$A19) | I19: 45383
A20: T6M average GM% (base, D-17) | D20: =AVERAGE(D14:D19)
A21: Apr-24 run-rate GM% (single month, D-17 sensitivity) | D21: =D19
A22: ARPA T6M avg by segment -> | E22: =AVERAGE(E14:E19) | F22: =AVERAGE(F14:F19) | G22: =AVERAGE(G14:G19)
A24: GM% selected (per Assumptions GM-basis selector) | B24: =IF(Assumptions!$B$7="T6M avg",D20,D21)
A26: Headline unit economics by segment (D-05/D-06/M-12..M-15; GM% uniform by construction -- see note above)
A27: Segment | B27: Marketing spend T6M | C27: Marketing spend T16M | D27: New paying customers T6M | E27: New paying customers T16M | F27: Allocated G&A T6M | G27: Allocated G&A T16M | H27: CAC fully loaded T6M | I27: CAC fully loaded T16M | J27: ARPA (T6M avg) | K27: GM% (selected) | L27: Revenue Apr-24 | M27: Lifetime, $ curve (60mo cap) | N27: LTV (60mo cap) | O27: LTV:CAC (T6M)
A28: B2C | B28: =SUMIFS(Data_Costs!$D$6:$D$149,Data_Costs!$B$6:$B$149,"B2C",Data_Costs!$A$6:$A$149,">="&Assumptions!$B$12,Data_Costs!$A$6:$A$149,"<="&Assumptions!$B$13) | C28: =SUMIFS(Data_Costs!$D$6:$D$149,Data_Costs!$B$6:$B$149,"B2C",Data_Costs!$A$6:$A$149,">="&Assumptions!$B$15,Data_Costs!$A$6:$A$149,"<="&Assumptions!$B$13) | D28: =SUMIFS(Data_Costs!$C$220:$C$299,Data_Costs!$B$220:$B$299,"B2C",Data_Costs!$A$220:$A$299,">="&Assumptions!$B$12,Data_Costs!$A$220:$A$299,"<="&Assumptions!$B$13) | E28: =SUMIFS(Data_Costs!$C$220:$C$299,Data_Costs!$B$220:$B$299,"B2C",Data_Costs!$A$220:$A$299,">="&Assumptions!$B$15,Data_Costs!$A$220:$A$299,"<="&Assumptions!$B$13) | F28: =$B$10*B28/$B$6 | G28: =$C$10*C28/$C$6 | H28: =(B28+F28)/D28 | I28: =(C28+G28)/E28 | J28: =$E$22 | K28: =$B$24 | L28: =SUMIFS(Data_MRR!$H$5:$H$84,Data_MRR!$B$5:$B$84,"B2C",Data_MRR!$A$5:$A$84,Assumptions!$B$10) | M28: =C94 | N28: =J28*K28*M28 | O28: =N28/H28
A29: SMB | B29: =SUMIFS(Data_Costs!$D$6:$D$149,Data_Costs!$B$6:$B$149,"SMB",Data_Costs!$A$6:$A$149,">="&Assumptions!$B$12,Data_Costs!$A$6:$A$149,"<="&Assumptions!$B$13) | C29: =SUMIFS(Data_Costs!$D$6:$D$149,Data_Costs!$B$6:$B$149,"SMB",Data_Costs!$A$6:$A$149,">="&Assumptions!$B$15,Data_Costs!$A$6:$A$149,"<="&Assumptions!$B$13) | D29: =SUMIFS(Data_Costs!$C$220:$C$299,Data_Costs!$B$220:$B$299,"SMB",Data_Costs!$A$220:$A$299,">="&Assumptions!$B$12,Data_Costs!$A$220:$A$299,"<="&Assumptions!$B$13) | E29: =SUMIFS(Data_Costs!$C$220:$C$299,Data_Costs!$B$220:$B$299,"SMB",Data_Costs!$A$220:$A$299,">="&Assumptions!$B$15,Data_Costs!$A$220:$A$299,"<="&Assumptions!$B$13) | F29: =$B$10*B29/$B$6 | G29: =$C$10*C29/$C$6 | H29: =(B29+F29)/D29 | I29: =(C29+G29)/E29 | J29: =$F$22 | K29: =$B$24 | L29: =SUMIFS(Data_MRR!$H$5:$H$84,Data_MRR!$B$5:$B$84,"SMB",Data_MRR!$A$5:$A$84,Assumptions!$B$10) | M29: =F94 | N29: =J29*K29*M29 | O29: =N29/H29
A30: Enterprise | B30: =SUMIFS(Data_Costs!$D$6:$D$149,Data_Costs!$B$6:$B$149,"Enterprise",Data_Costs!$A$6:$A$149,">="&Assumptions!$B$12,Data_Costs!$A$6:$A$149,"<="&Assumptions!$B$13) | C30: =SUMIFS(Data_Costs!$D$6:$D$149,Data_Costs!$B$6:$B$149,"Enterprise",Data_Costs!$A$6:$A$149,">="&Assumptions!$B$15,Data_Costs!$A$6:$A$149,"<="&Assumptions!$B$13) | D30: =SUMIFS(Data_Costs!$C$220:$C$299,Data_Costs!$B$220:$B$299,"Enterprise",Data_Costs!$A$220:$A$299,">="&Assumptions!$B$12,Data_Costs!$A$220:$A$299,"<="&Assumptions!$B$13) | E30: =SUMIFS(Data_Costs!$C$220:$C$299,Data_Costs!$B$220:$B$299,"Enterprise",Data_Costs!$A$220:$A$299,">="&Assumptions!$B$15,Data_Costs!$A$220:$A$299,"<="&Assumptions!$B$13) | F30: =$B$10*B30/$B$6 | G30: =$C$10*C30/$C$6 | H30: =(B30+F30)/D30 | I30: =(C30+G30)/E30 | J30: =$G$22 | K30: =$B$24 | L30: =SUMIFS(Data_MRR!$H$5:$H$84,Data_MRR!$B$5:$B$84,"Enterprise",Data_MRR!$A$5:$A$84,Assumptions!$B$10) | M30: =I94 | N30: =J30*K30*M30 | O30: =N30/H30
A31: Total | B31: =SUM(B28:B30) | C31: =SUM(C28:C30) | D31: =SUM(D28:D30) | E31: =SUM(E28:E30) | F31: =$B$10*B31/$B$6 | G31: =$C$10*C31/$C$6 | H31: =(B31+F31)/D31 | I31: =(C31+G31)/E31 | J31: =AVERAGE(E22:G22) | K31: =$B$24 | L31: =SUMIFS(Data_MRR!$H$5:$H$84,Data_MRR!$B$5:$B$84,"Total",Data_MRR!$A$5:$A$84,Assumptions!$B$10) | M31: =SUMPRODUCT(D28:D30,M28:M30)/D31 | N31: =SUMPRODUCT(D28:D30,N28:N30)/D31 | O31: =N31/H31
A33: 60-month lifetime curve, $ basis (M-14; A-15..A-18, A-23): observed dollar retention for k=0..k_rel (Data_Survival), then an extrapolated geometric tail using each segment's tail decay rate (Assumptions). Lifetime = sum of the curve.
A34: k (months since signup) | B34: B2C curve | C34: B2C cumulative (=lifetime thru k) | D34: B2C cum. gross profit/cust | E34: SMB curve | F34: SMB cumulative (=lifetime thru k) | G34: SMB cum. gross profit/cust | H34: Enterprise curve | I34: Enterprise cumulative (=lifetime thru k) | J34: Enterprise cum. gross profit/cust
A35: 0 | B35: =SUMIFS(Data_Survival!$H$5:$H$84,Data_Survival!$A$5:$A$84,"B2C",Data_Survival!$B$5:$B$84,$A35) | C35: =B35 | D35: =C35*$E$22*$B$24 | E35: =SUMIFS(Data_Survival!$H$5:$H$84,Data_Survival!$A$5:$A$84,"SMB",Data_Survival!$B$5:$B$84,$A35) | F35: =E35 | G35: =F35*$F$22*$B$24 | H35: =SUMIFS(Data_Survival!$H$5:$H$84,Data_Survival!$A$5:$A$84,"Enterprise",Data_Survival!$B$5:$B$84,$A35) | I35: =H35 | J35: =I35*$G$22*$B$24
A36: 1 | B36: =IF($A36<=Assumptions!$B$44,SUMIFS(Data_Survival!$H$5:$H$84,Data_Survival!$A$5:$A$84,"B2C",Data_Survival!$B$5:$B$84,$A36),B35*(1-Assumptions!$C$44)) | C36: =C35+B36 | D36: =C36*$E$22*$B$24 | E36: =IF($A36<=Assumptions!$B$45,SUMIFS(Data_Survival!$H$5:$H$84,Data_Survival!$A$5:$A$84,"SMB",Data_Survival!$B$5:$B$84,$A36),E35*(1-Assumptions!$C$45)) | F36: =F35+E36 | G36: =F36*$F$22*$B$24 | H36: =IF($A36<=Assumptions!$B$46,SUMIFS(Data_Survival!$H$5:$H$84,Data_Survival!$A$5:$A$84,"Enterprise",Data_Survival!$B$5:$B$84,$A36),H35*(1-Assumptions!$C$46)) | I36: =I35+H36 | J36: =I36*$G$22*$B$24
A37: 2 | B37: =IF($A37<=Assumptions!$B$44,SUMIFS(Data_Survival!$H$5:$H$84,Data_Survival!$A$5:$A$84,"B2C",Data_Survival!$B$5:$B$84,$A37),B36*(1-Assumptions!$C$44)) | C37: =C36+B37 | D37: =C37*$E$22*$B$24 | E37: =IF($A37<=Assumptions!$B$45,SUMIFS(Data_Survival!$H$5:$H$84,Data_Survival!$A$5:$A$84,"SMB",Data_Survival!$B$5:$B$84,$A37),E36*(1-Assumptions!$C$45)) | F37: =F36+E37 | G37: =F37*$F$22*$B$24 | H37: =IF($A37<=Assumptions!$B$46,SUMIFS(Data_Survival!$H$5:$H$84,Data_Survival!$A$5:$A$84,"Enterprise",Data_Survival!$B$5:$B$84,$A37),H36*(1-Assumptions!$C$46)) | I37: =I36+H37 | J37: =I37*$G$22*$B$24
A38: 3 | B38: =IF($A38<=Assumptions!$B$44,SUMIFS(Data_Survival!$H$5:$H$84,Data_Survival!$A$5:$A$84,"B2C",Data_Survival!$B$5:$B$84,$A38),B37*(1-Assumptions!$C$44)) | C38: =C37+B38 | D38: =C38*$E$22*$B$24 | E38: =IF($A38<=Assumptions!$B$45,SUMIFS(Data_Survival!$H$5:$H$84,Data_Survival!$A$5:$A$84,"SMB",Data_Survival!$B$5:$B$84,$A38),E37*(1-Assumptions!$C$45)) | F38: =F37+E38 | G38: =F38*$F$22*$B$24 | H38: =IF($A38<=Assumptions!$B$46,SUMIFS(Data_Survival!$H$5:$H$84,Data_Survival!$A$5:$A$84,"Enterprise",Data_Survival!$B$5:$B$84,$A38),H37*(1-Assumptions!$C$46)) | I38: =I37+H38 | J38: =I38*$G$22*$B$24
A39: 4 | B39: =IF($A39<=Assumptions!$B$44,SUMIFS(Data_Survival!$H$5:$H$84,Data_Survival!$A$5:$A$84,"B2C",Data_Survival!$B$5:$B$84,$A39),B38*(1-Assumptions!$C$44)) | C39: =C38+B39 | D39: =C39*$E$22*$B$24 | E39: =IF($A39<=Assumptions!$B$45,SUMIFS(Data_Survival!$H$5:$H$84,Data_Survival!$A$5:$A$84,"SMB",Data_Survival!$B$5:$B$84,$A39),E38*(1-Assumptions!$C$45)) | F39: =F38+E39 | G39: =F39*$F$22*$B$24 | H39: =IF($A39<=Assumptions!$B$46,SUMIFS(Data_Survival!$H$5:$H$84,Data_Survival!$A$5:$A$84,"Enterprise",Data_Survival!$B$5:$B$84,$A39),H38*(1-Assumptions!$C$46)) | I39: =I38+H39 | J39: =I39*$G$22*$B$24
A40: 5 | B40: =IF($A40<=Assumptions!$B$44,SUMIFS(Data_Survival!$H$5:$H$84,Data_Survival!$A$5:$A$84,"B2C",Data_Survival!$B$5:$B$84,$A40),B39*(1-Assumptions!$C$44)) | C40: =C39+B40 | D40: =C40*$E$22*$B$24 | E40: =IF($A40<=Assumptions!$B$45,SUMIFS(Data_Survival!$H$5:$H$84,Data_Survival!$A$5:$A$84,"SMB",Data_Survival!$B$5:$B$84,$A40),E39*(1-Assumptions!$C$45)) | F40: =F39+E40 | G40: =F40*$F$22*$B$24 | H40: =IF($A40<=Assumptions!$B$46,SUMIFS(Data_Survival!$H$5:$H$84,Data_Survival!$A$5:$A$84,"Enterprise",Data_Survival!$B$5:$B$84,$A40),H39*(1-Assumptions!$C$46)) | I40: =I39+H40 | J40: =I40*$G$22*$B$24
A41: 6 | B41: =IF($A41<=Assumptions!$B$44,SUMIFS(Data_Survival!$H$5:$H$84,Data_Survival!$A$5:$A$84,"B2C",Data_Survival!$B$5:$B$84,$A41),B40*(1-Assumptions!$C$44)) | C41: =C40+B41 | D41: =C41*$E$22*$B$24 | E41: =IF($A41<=Assumptions!$B$45,SUMIFS(Data_Survival!$H$5:$H$84,Data_Survival!$A$5:$A$84,"SMB",Data_Survival!$B$5:$B$84,$A41),E40*(1-Assumptions!$C$45)) | F41: =F40+E41 | G41: =F41*$F$22*$B$24 | H41: =IF($A41<=Assumptions!$B$46,SUMIFS(Data_Survival!$H$5:$H$84,Data_Survival!$A$5:$A$84,"Enterprise",Data_Survival!$B$5:$B$84,$A41),H40*(1-Assumptions!$C$46)) | I41: =I40+H41 | J41: =I41*$G$22*$B$24
A42: 7 | B42: =IF($A42<=Assumptions!$B$44,SUMIFS(Data_Survival!$H$5:$H$84,Data_Survival!$A$5:$A$84,"B2C",Data_Survival!$B$5:$B$84,$A42),B41*(1-Assumptions!$C$44)) | C42: =C41+B42 | D42: =C42*$E$22*$B$24 | E42: =IF($A42<=Assumptions!$B$45,SUMIFS(Data_Survival!$H$5:$H$84,Data_Survival!$A$5:$A$84,"SMB",Data_Survival!$B$5:$B$84,$A42),E41*(1-Assumptions!$C$45)) | F42: =F41+E42 | G42: =F42*$F$22*$B$24 | H42: =IF($A42<=Assumptions!$B$46,SUMIFS(Data_Survival!$H$5:$H$84,Data_Survival!$A$5:$A$84,"Enterprise",Data_Survival!$B$5:$B$84,$A42),H41*(1-Assumptions!$C$46)) | I42: =I41+H42 | J42: =I42*$G$22*$B$24
A43: 8 | B43: =IF($A43<=Assumptions!$B$44,SUMIFS(Data_Survival!$H$5:$H$84,Data_Survival!$A$5:$A$84,"B2C",Data_Survival!$B$5:$B$84,$A43),B42*(1-Assumptions!$C$44)) | C43: =C42+B43 | D43: =C43*$E$22*$B$24 | E43: =IF($A43<=Assumptions!$B$45,SUMIFS(Data_Survival!$H$5:$H$84,Data_Survival!$A$5:$A$84,"SMB",Data_Survival!$B$5:$B$84,$A43),E42*(1-Assumptions!$C$45)) | F43: =F42+E43 | G43: =F43*$F$22*$B$24 | H43: =IF($A43<=Assumptions!$B$46,SUMIFS(Data_Survival!$H$5:$H$84,Data_Survival!$A$5:$A$84,"Enterprise",Data_Survival!$B$5:$B$84,$A43),H42*(1-Assumptions!$C$46)) | I43: =I42+H43 | J43: =I43*$G$22*$B$24
A44: 9 | B44: =IF($A44<=Assumptions!$B$44,SUMIFS(Data_Survival!$H$5:$H$84,Data_Survival!$A$5:$A$84,"B2C",Data_Survival!$B$5:$B$84,$A44),B43*(1-Assumptions!$C$44)) | C44: =C43+B44 | D44: =C44*$E$22*$B$24 | E44: =IF($A44<=Assumptions!$B$45,SUMIFS(Data_Survival!$H$5:$H$84,Data_Survival!$A$5:$A$84,"SMB",Data_Survival!$B$5:$B$84,$A44),E43*(1-Assumptions!$C$45)) | F44: =F43+E44 | G44: =F44*$F$22*$B$24 | H44: =IF($A44<=Assumptions!$B$46,SUMIFS(Data_Survival!$H$5:$H$84,Data_Survival!$A$5:$A$84,"Enterprise",Data_Survival!$B$5:$B$84,$A44),H43*(1-Assumptions!$C$46)) | I44: =I43+H44 | J44: =I44*$G$22*$B$24
A45: 10 | B45: =IF($A45<=Assumptions!$B$44,SUMIFS(Data_Survival!$H$5:$H$84,Data_Survival!$A$5:$A$84,"B2C",Data_Survival!$B$5:$B$84,$A45),B44*(1-Assumptions!$C$44)) | C45: =C44+B45 | D45: =C45*$E$22*$B$24 | E45: =IF($A45<=Assumptions!$B$45,SUMIFS(Data_Survival!$H$5:$H$84,Data_Survival!$A$5:$A$84,"SMB",Data_Survival!$B$5:$B$84,$A45),E44*(1-Assumptions!$C$45)) | F45: =F44+E45 | G45: =F45*$F$22*$B$24 | H45: =IF($A45<=Assumptions!$B$46,SUMIFS(Data_Survival!$H$5:$H$84,Data_Survival!$A$5:$A$84,"Enterprise",Data_Survival!$B$5:$B$84,$A45),H44*(1-Assumptions!$C$46)) | I45: =I44+H45 | J45: =I45*$G$22*$B$24
...

Sheet Scenarios
A1: Scenarios
A2: A simplified, formula-driven 12-month (May-24..Apr-25) projection by segment, in three parallel Base/Bull/Bear blocks (no selector needed -- all three are always computed). Simplification vs. the Python engine (sql/python_models/scenarios.py): this sheet tracks ONE bucket per segment (not per plan_type), blends monthly/annual rates using the Apr-24 stock mix (churn) and the T6M new-customer plan mix (ARPA) held constant for the whole horizon, and does not model the B2C monthly->annual migration lever. See the reconciliation block at the bottom (target <= 3% gap on Apr-25 total MRR).
A4: Blended driver build (per segment): stock-mix-weighted churn, new-customer-mix ARPA blend, and the Base/Bull/Bear variant of each rate -- all linked to Assumptions (no hard-coded numbers)
A5: Segment | B5: Stock share, monthly (Apr-24) | C5: Stock share, annual (Apr-24) | D5: Churn blend, Base | E5: Churn blend, Bull | F5: Churn blend, Bear | G5: New-cust ARPA blend | H5: Expansion, Base | I5: Expansion, Bull | J5: Expansion, Bear | K5: Contraction, Base | L5: Contraction, Bull | M5: Contraction, Bear | N5: New customers/mo, Base | O5: Trend slope/mo (Bull)
A6: B2C | B6: =SUMIFS(Assumptions!$C$29:$C$34,Assumptions!$A$29:$A$34,"B2C",Assumptions!$B$29:$B$34,"monthly")/(SUMIFS(Assumptions!$C$29:$C$34,Assumptions!$A$29:$A$34,"B2C",Assumptions!$B$29:$B$34,"monthly")+SUMIFS(Assumptions!$C$29:$C$34,Assumptions!$A$29:$A$34,"B2C",Assumptions!$B$29:$B$34,"annual")) | C6: =1-B6 | D6: =B6*Assumptions!$B$57+C6*Assumptions!$B$58 | E6: =B6*Assumptions!$B$57*(1-Assumptions!$B$71)+C6*Assumptions!$B$58 | F6: =D6*(1+Assumptions!$B$65) | G6: =Assumptions!$B$55*Assumptions!$B$53+Assumptions!$B$56*Assumptions!$B$54 | H6: =Assumptions!$B$59 | I6: =Assumptions!$B$59 | J6: =Assumptions!$B$59 | K6: =Assumptions!$B$60 | L6: =Assumptions!$B$60 | M6: =Assumptions!$B$60 | N6: =Assumptions!$B$51 | O6: =Assumptions!$B$52
A7: SMB | B7: =SUMIFS(Assumptions!$C$29:$C$34,Assumptions!$A$29:$A$34,"SMB",Assumptions!$B$29:$B$34,"monthly")/(SUMIFS(Assumptions!$C$29:$C$34,Assumptions!$A$29:$A$34,"SMB",Assumptions!$B$29:$B$34,"monthly")+SUMIFS(Assumptions!$C$29:$C$34,Assumptions!$A$29:$A$34,"SMB",Assumptions!$B$29:$B$34,"annual")) | C7: =1-B7 | D7: =B7*Assumptions!$C$57+C7*Assumptions!$C$58 | E7: =B7*Assumptions!$C$57*(1-Assumptions!$B$71)+C7*Assumptions!$C$58 | F7: =D7*(1+Assumptions!$B$65) | G7: =Assumptions!$C$55*Assumptions!$C$53+Assumptions!$C$56*Assumptions!$C$54 | H7: =Assumptions!$C$59 | I7: =Assumptions!$C$59*(1+Assumptions!$B$73) | J7: =Assumptions!$C$59*Assumptions!$B$66 | K7: =Assumptions!$C$60 | L7: =Assumptions!$C$60 | M7: =Assumptions!$C$60 | N7: =Assumptions!$C$51 | O7: =Assumptions!$C$52
A8: Enterprise | B8: =SUMIFS(Assumptions!$C$29:$C$34,Assumptions!$A$29:$A$34,"Enterprise",Assumptions!$B$29:$B$34,"monthly")/(SUMIFS(Assumptions!$C$29:$C$34,Assumptions!$A$29:$A$34,"Enterprise",Assumptions!$B$29:$B$34,"monthly")+SUMIFS(Assumptions!$C$29:$C$34,Assumptions!$A$29:$A$34,"Enterprise",Assumptions!$B$29:$B$34,"annual")) | C8: =1-B8 | D8: =B8*Assumptions!$D$57+C8*Assumptions!$D$58 | E8: =B8*Assumptions!$D$57*(1-Assumptions!$B$71)+C8*Assumptions!$D$58 | F8: =D8*(1+Assumptions!$B$65) | G8: =Assumptions!$D$55*Assumptions!$D$53+Assumptions!$D$56*Assumptions!$D$54 | H8: =Assumptions!$D$59 | I8: =Assumptions!$D$59 | J8: =Assumptions!$D$59*Assumptions!$B$67 | K8: =Assumptions!$D$60 | L8: =Assumptions!$D$60*(1-Assumptions!$B$74) | M8: =Assumptions!$D$60 | N8: =Assumptions!$D$51 | O8: =Assumptions!$D$52
A10: Scenario: Base -- 12-month projection by segment (May-24..Apr-25)
A11: Base / B2C
A12: Month # | B12: Opening customers | C12: New customers | D12: Churn customers | E12: Closing customers | F12: Opening MRR | G12: New MRR | H12: Expansion MRR | I12: Contraction MRR | J12: Churn MRR | K12: Closing MRR
A13: 1 | B13: =SUMIFS(Data_MRR!$I:$I,Data_MRR!$B:$B,"B2C",Data_MRR!$A:$A,Assumptions!$B$10) | C13: =$N$6 | D13: =B13*$D$6 | E13: =B13-D13+C13 | F13: =SUMIFS(Data_MRR!$H:$H,Data_MRR!$B:$B,"B2C",Data_MRR!$A:$A,Assumptions!$B$10) | G13: =C13*$G$6 | H13: =F13*$H$6 | I13: =F13*$K$6 | J13: =F13*$D$6 | K13: =F13-J13+G13+H13-I13
A14: 2 | B14: =E13 | C14: =$N$6 | D14: =B14*$D$6 | E14: =B14-D14+C14 | F14: =K13 | G14: =C14*$G$6 | H14: =F14*$H$6 | I14: =F14*$K$6 | J14: =F14*$D$6 | K14: =F14-J14+G14+H14-I14
A15: 3 | B15: =E14 | C15: =$N$6 | D15: =B15*$D$6 | E15: =B15-D15+C15 | F15: =K14 | G15: =C15*$G$6 | H15: =F15*$H$6 | I15: =F15*$K$6 | J15: =F15*$D$6 | K15: =F15-J15+G15+H15-I15
A16: 4 | B16: =E15 | C16: =$N$6 | D16: =B16*$D$6 | E16: =B16-D16+C16 | F16: =K15 | G16: =C16*$G$6 | H16: =F16*$H$6 | I16: =F16*$K$6 | J16: =F16*$D$6 | K16: =F16-J16+G16+H16-I16
A17: 5 | B17: =E16 | C17: =$N$6 | D17: =B17*$D$6 | E17: =B17-D17+C17 | F17: =K16 | G17: =C17*$G$6 | H17: =F17*$H$6 | I17: =F17*$K$6 | J17: =F17*$D$6 | K17: =F17-J17+G17+H17-I17
A18: 6 | B18: =E17 | C18: =$N$6 | D18: =B18*$D$6 | E18: =B18-D18+C18 | F18: =K17 | G18: =C18*$G$6 | H18: =F18*$H$6 | I18: =F18*$K$6 | J18: =F18*$D$6 | K18: =F18-J18+G18+H18-I18
A19: 7 | B19: =E18 | C19: =$N$6 | D19: =B19*$D$6 | E19: =B19-D19+C19 | F19: =K18 | G19: =C19*$G$6 | H19: =F19*$H$6 | I19: =F19*$K$6 | J19: =F19*$D$6 | K19: =F19-J19+G19+H19-I19
A20: 8 | B20: =E19 | C20: =$N$6 | D20: =B20*$D$6 | E20: =B20-D20+C20 | F20: =K19 | G20: =C20*$G$6 | H20: =F20*$H$6 | I20: =F20*$K$6 | J20: =F20*$D$6 | K20: =F20-J20+G20+H20-I20
A21: 9 | B21: =E20 | C21: =$N$6 | D21: =B21*$D$6 | E21: =B21-D21+C21 | F21: =K20 | G21: =C21*$G$6 | H21: =F21*$H$6 | I21: =F21*$K$6 | J21: =F21*$D$6 | K21: =F21-J21+G21+H21-I21
A22: 10 | B22: =E21 | C22: =$N$6 | D22: =B22*$D$6 | E22: =B22-D22+C22 | F22: =K21 | G22: =C22*$G$6 | H22: =F22*$H$6 | I22: =F22*$K$6 | J22: =F22*$D$6 | K22: =F22-J22+G22+H22-I22
A23: 11 | B23: =E22 | C23: =$N$6 | D23: =B23*$D$6 | E23: =B23-D23+C23 | F23: =K22 | G23: =C23*$G$6 | H23: =F23*$H$6 | I23: =F23*$K$6 | J23: =F23*$D$6 | K23: =F23-J23+G23+H23-I23
A24: 12 | B24: =E23 | C24: =$N$6 | D24: =B24*$D$6 | E24: =B24-D24+C24 | F24: =K23 | G24: =C24*$G$6 | H24: =F24*$H$6 | I24: =F24*$K$6 | J24: =F24*$D$6 | K24: =F24-J24+G24+H24-I24
A26: Base / SMB
A27: Month # | B27: Opening customers | C27: New customers | D27: Churn customers | E27: Closing customers | F27: Opening MRR | G27: New MRR | H27: Expansion MRR | I27: Contraction MRR | J27: Churn MRR | K27: Closing MRR
A28: 1 | B28: =SUMIFS(Data_MRR!$I:$I,Data_MRR!$B:$B,"SMB",Data_MRR!$A:$A,Assumptions!$B$10) | C28: =$N$7 | D28: =B28*$D$7 | E28: =B28-D28+C28 | F28: =SUMIFS(Data_MRR!$H:$H,Data_MRR!$B:$B,"SMB",Data_MRR!$A:$A,Assumptions!$B$10) | G28: =C28*$G$7 | H28: =F28*$H$7 | I28: =F28*$K$7 | J28: =F28*$D$7 | K28: =F28-J28+G28+H28-I28
A29: 2 | B29: =E28 | C29: =$N$7 | D29: =B29*$D$7 | E29: =B29-D29+C29 | F29: =K28 | G29: =C29*$G$7 | H29: =F29*$H$7 | I29: =F29*$K$7 | J29: =F29*$D$7 | K29: =F29-J29+G29+H29-I29
A30: 3 | B30: =E29 | C30: =$N$7 | D30: =B30*$D$7 | E30: =B30-D30+C30 | F30: =K29 | G30: =C30*$G$7 | H30: =F30*$H$7 | I30: =F30*$K$7 | J30: =F30*$D$7 | K30: =F30-J30+G30+H30-I30
A31: 4 | B31: =E30 | C31: =$N$7 | D31: =B31*$D$7 | E31: =B31-D31+C31 | F31: =K30 | G31: =C31*$G$7 | H31: =F31*$H$7 | I31: =F31*$K$7 | J31: =F31*$D$7 | K31: =F31-J31+G31+H31-I31
A32: 5 | B32: =E31 | C32: =$N$7 | D32: =B32*$D$7 | E32: =B32-D32+C32 | F32: =K31 | G32: =C32*$G$7 | H32: =F32*$H$7 | I32: =F32*$K$7 | J32: =F32*$D$7 | K32: =F32-J32+G32+H32-I32
A33: 6 | B33: =E32 | C33: =$N$7 | D33: =B33*$D$7 | E33: =B33-D33+C33 | F33: =K32 | G33: =C33*$G$7 | H33: =F33*$H$7 | I33: =F33*$K$7 | J33: =F33*$D$7 | K33: =F33-J33+G33+H33-I33
A34: 7 | B34: =E33 | C34: =$N$7 | D34: =B34*$D$7 | E34: =B34-D34+C34 | F34: =K33 | G34: =C34*$G$7 | H34: =F34*$H$7 | I34: =F34*$K$7 | J34: =F34*$D$7 | K34: =F34-J34+G34+H34-I34
A35: 8 | B35: =E34 | C35: =$N$7 | D35: =B35*$D$7 | E35: =B35-D35+C35 | F35: =K34 | G35: =C35*$G$7 | H35: =F35*$H$7 | I35: =F35*$K$7 | J35: =F35*$D$7 | K35: =F35-J35+G35+H35-I35
A36: 9 | B36: =E35 | C36: =$N$7 | D36: =B36*$D$7 | E36: =B36-D36+C36 | F36: =K35 | G36: =C36*$G$7 | H36: =F36*$H$7 | I36: =F36*$K$7 | J36: =F36*$D$7 | K36: =F36-J36+G36+H36-I36
A37: 10 | B37: =E36 | C37: =$N$7 | D37: =B37*$D$7 | E37: =B37-D37+C37 | F37: =K36 | G37: =C37*$G$7 | H37: =F37*$H$7 | I37: =F37*$K$7 | J37: =F37*$D$7 | K37: =F37-J37+G37+H37-I37
A38: 11 | B38: =E37 | C38: =$N$7 | D38: =B38*$D$7 | E38: =B38-D38+C38 | F38: =K37 | G38: =C38*$G$7 | H38: =F38*$H$7 | I38: =F38*$K$7 | J38: =F38*$D$7 | K38: =F38-J38+G38+H38-I38
A39: 12 | B39: =E38 | C39: =$N$7 | D39: =B39*$D$7 | E39: =B39-D39+C39 | F39: =K38 | G39: =C39*$G$7 | H39: =F39*$H$7 | I39: =F39*$K$7 | J39: =F39*$D$7 | K39: =F39-J39+G39+H39-I39
A41: Base / Enterprise
A42: Month # | B42: Opening customers | C42: New customers | D42: Churn customers | E42: Closing customers | F42: Opening MRR | G42: New MRR | H42: Expansion MRR | I42: Contraction MRR | J42: Churn MRR | K42: Closing MRR
A43: 1 | B43: =SUMIFS(Data_MRR!$I:$I,Data_MRR!$B:$B,"Enterprise",Data_MRR!$A:$A,Assumptions!$B$10) | C43: =$N$8 | D43: =B43*$D$8 | E43: =B43-D43+C43 | F43: =SUMIFS(Data_MRR!$H:$H,Data_MRR!$B:$B,"Enterprise",Data_MRR!$A:$A,Assumptions!$B$10) | G43: =C43*$G$8 | H43: =F43*$H$8 | I43: =F43*$K$8 | J43: =F43*$D$8 | K43: =F43-J43+G43+H43-I43
A44: 2 | B44: =E43 | C44: =$N$8 | D44: =B44*$D$8 | E44: =B44-D44+C44 | F44: =K43 | G44: =C44*$G$8 | H44: =F44*$H$8 | I44: =F44*$K$8 | J44: =F44*$D$8 | K44: =F44-J44+G44+H44-I44
...

Sheet Strategies
A1: Strategies
A2: Source: WP23 results.md + mart_s_04_strategy_impact (from the Python scenario engine, sql/python_models/scenarios.py -- each strategy is sized as an isolated lever on top of the Base scenario). The company-wide 6mo/12mo MRR and NDR deltas are simulation outputs ('from engine', not spreadsheet formulas -- the underlying monthly compartment simulation is not re-derived here, same as the Scenarios tab's engine comparison). One illustrative figure IS a simple in-sheet formula: Strategy-1's immediate monthly save on the concrete May-24 at-risk list.
A4: Illustrative simple-formula check: Strategy-1 applied to the May-24 at-risk list (source: mart_a1_06_may24_churn_risk, D-16 risk tiers)
A5: Metric | B5: Value | C5: Unit | D5: Source
A6: May-24 High+Medium risk MRR (flagged) | B6: =Assumptions!$B$77 | C6: USD | D6: Assumptions (mart_a1_06_may24_churn_risk)
A7: ...of which expected to churn (mrr_at_risk) | B7: =Assumptions!$B$78 | C7: USD | D7: Assumptions (mart_a1_06_may24_churn_risk)
A8: Strategy-1 base-case save rate (link to Assumptions) | B8: =Assumptions!$B$71 | C8: fraction saved | D8: A-20 (Assumptions)
A9: -> Immediate monthly MRR saved if applied once to the May-24 list | B9: =B7*B8 | C9: USD/month | D9: simple formula (at-risk MRR x save rate)
A11: This single-month figure is smaller than the engine's $7,690/6-month company number below because the engine compounds the same save rate over every month's newly flagged cohort, not just the May-24 list once (see WP23 results.md).
A13: Company-wide strategy impact, low/base/high (from engine: mart_s_04_strategy_impact)
A14: Strategy | B14: Case | C14: 6-mo MRR impact ($) | D14: 6-mo MRR impact (%) | E14: 12-mo MRR impact ($) | F14: NDR impact, 6-mo (pp) | G14: Effort | H14: Time to impact (months)
A15: 1. Engagement alert + save play | B15: low | C15: 3763.0281 | D15: 0.013269798 | E15: 6607.6738 | F15: 1.3113409 | G15: Low | H15: 1
A16: 1. Engagement alert + save play | B16: base | C16: 7690.0102 | D16: 0.027117757 | E16: 13783.118 | F16: 2.6890724 | G16: Low | H16: 1
A17: 1. Engagement alert + save play | B17: high | C17: 11787.322 | D17: 0.041566362 | E17: 21578.618 | F17: 4.1359909 | G17: Low | H17: 1
A18: 2. B2C monthly -> annual migration | B18: low | C18: -455.90918 | D18: -0.0016077007 | E18: 754.72421 | F18: -0.10351744 | G18: Medium | H18: 6
A19: 2. B2C monthly -> annual migration | B19: base | C19: -849.63982 | D19: -0.0029961373 | E19: 1529.2761 | F19: -0.1837432 | G19: Medium | H19: 6
A20: 2. B2C monthly -> annual migration | B20: high | C20: -1186.6522 | D20: -0.004184565 | E20: 2308.591 | F20: -0.2430074 | G20: Medium | H20: 6
A21: 3. B2B expansion/contraction playbook | B21: low | C21: 810.33067 | D21: 0.002857519 | E21: 1828.8675 | F21: 0.31637505 | G21: Medium | H21: 3
A22: 3. B2B expansion/contraction playbook | B22: base | C22: 1559.3557 | D22: 0.0054988523 | E22: 3528.9993 | F22: 0.60887707 | G22: Medium | H22: 3
A23: 3. B2B expansion/contraction playbook | B23: high | C23: 2313.3976 | D23: 0.0081578767 | E23: 5252.8431 | F23: 0.9035438 | G23: Medium | H23: 3
A25: Recommended sequence (WP23; unchanged narrative from the engine's own numbers above)
A26: 1) Engagement alert (Strategy 1) -- ship first: cheapest, fastest, biggest single lever (Low effort, 1 month to impact).
A27: 2) B2B playbook (Strategy 3) -- run in parallel: positive, no MRR downside, Medium effort.
